Workbook
Name cd_Cats: OFFSET(Chart_Data!$B$2,0,0,COUNT(Chart_Data!$J$2:$J$401),1)
Name cd_Dates: OFFSET(Chart_Data!$C$2,0,0,COUNT(Chart_Data!$J$2:$J$401),1)
Name cd_DILRpc: OFFSET(Chart_Data!$G$2,0,0,COUNT(Chart_Data!$J$2:$J$401),1)
Name cd_DILRsc: OFFSET(Chart_Data!$F$2,0,0,COUNT(Chart_Data!$J$2:$J$401),1)
Name cd_Idx: OFFSET(Chart_Data!$A$2,0,0,COUNT(Chart_Data!$J$2:$J$401),1)
Name cd_Ovrpc: OFFSET(Chart_Data!$K$2,0,0,COUNT(Chart_Data!$J$2:$J$401),1)
Name cd_Ovrsc: OFFSET(Chart_Data!$J$2,0,0,COUNT(Chart_Data!$J$2:$J$401),1)
Name cd_QApc: OFFSET(Chart_Data!$I$2,0,0,COUNT(Chart_Data!$J$2:$J$401),1)
Name cd_QAsc: OFFSET(Chart_Data!$H$2,0,0,COUNT(Chart_Data!$J$2:$J$401),1)
Name cd_VARCpc: OFFSET(Chart_Data!$E$2,0,0,COUNT(Chart_Data!$J$2:$J$401),1)
Name cd_VARCsc: OFFSET(Chart_Data!$D$2,0,0,COUNT(Chart_Data!$J$2:$J$401),1)
Name cn_DILRpc: OFFSET(Chart_Data!$R$2,0,0,COUNT(Chart_Data!$J$2:$J$401),1)
Name cn_DILRsc: OFFSET(Chart_Data!$Q$2,0,0,COUNT(Chart_Data!$J$2:$J$401),1)
Name cn_Ovrpc: OFFSET(Chart_Data!$V$2,0,0,COUNT(Chart_Data!$J$2:$J$401),1)
Name cn_Ovrsc: OFFSET(Chart_Data!$U$2,0,0,COUNT(Chart_Data!$J$2:$J$401),1)
Name cn_QApc: OFFSET(Chart_Data!$T$2,0,0,COUNT(Chart_Data!$J$2:$J$401),1)
Name cn_QAsc: OFFSET(Chart_Data!$S$2,0,0,COUNT(Chart_Data!$J$2:$J$401),1)
Name cn_VARCpc: OFFSET(Chart_Data!$P$2,0,0,COUNT(Chart_Data!$J$2:$J$401),1)
Name cn_VARCsc: OFFSET(Chart_Data!$O$2,0,0,COUNT(Chart_Data!$J$2:$J$401),1)
Name lst_Analysis: OFFSET(Lists!$D$2,0,0,COUNTA(Lists!$D$2:$D$100),1)
Name lst_MockTypes: OFFSET(Lists!$C$2,0,0,COUNTA(Lists!$C$2:$C$100),1)
Name lst_Providers: OFFSET(Lists!$A$2,0,0,COUNTA(Lists!$A$2:$A$100),1)
Name lst_Series: OFFSET(Lists!$B$2,0,0,COUNTA(Lists!$B$2:$B$100),1)

Sheet Dashboard
A1: 🎯 CAT 2026 — Mock Analytics Dashboard | O1: ✦ Made by Devansh Gohil
A2: IMS SimCAT Schedule · CAT Date: 29 Nov 2026 · 150 pre-created rows · Formula-driven analytics
A3: =Calculations!B29 -> 111 | D3: =TEXT(Calculations!B23,"0")&" / "&TEXT(Calculations!B22,"0") -> 10 / 100 | G3: =TEXT(Calculations!B25,"0.0%") -> 10.0% | J3: =TEXT(Calculations!B26,"0")&" / "&TEXT(Calculations!B23,"0") -> 10 / 10 | M3: =TEXT(Calculations!B30,"DD-MMM-YYYY") -> 13-Jul-2026
A4: DAYS TO CAT | D4: COMPLETED / PLANNED | G4: COMPLETION RATE | J4: ANALYSED | M4: LAST ATTEMPTED
A6: ◈ Overall | E6: ◈ VARC | I6: ◈ DILR | M6: ◈ QA
A7: Metric | B7: Score | C7: %ile | D7: Δ | E7: Metric | F7: Score | G7: %ile | H7: Δ | I7: Metric | J7: Score | K7: %ile | L7: Δ | M7: Metric | N7: Score | O7: %ile | P7: Δ
A8: Latest | B8: =IFERROR(Calculations!B2,"—") -> 55 | C8: =IFERROR(Calculations!C2,"—") -> 79.22 | D8: =IFERROR(IF(Calculations!B2>=Calculations!B3,"▲","▼"),"—") -> ▼ | E8: Latest | F8: =IFERROR(Calculations!D2,"—") -> 20 | G8: =IFERROR(Calculations!E2,"—") -> 65.51 | H8: =IFERROR(IF(Calculations!D2>=Calculations!D3,"▲","▼"),"—") -> ▼ | I8: Latest | J8: =IFERROR(Calculations!F2,"—") -> 16 | K8: =IFERROR(Calculations!G2,"—") -> 83.74 | L8: =IFERROR(IF(Calculations!F2>=Calculations!F3,"▲","▼"),"—") -> ▼ | M8: Latest | N8: =IFERROR(Calculations!H2,"—") -> 19 | O8: =IFERROR(Calculations!I2,"—") -> 69.82 | P8: =IFERROR(IF(Calculations!H2>=Calculations!H3,"▲","▼"),"—") -> ▼ | R8: 🗓 Planned Mocks by Month
A9: Average | B9: =IFERROR(Calculations!B3,"—") -> 79.1 | C9: =IFERROR(Calculations!C3,"—") -> 92.015556 | E9: Average | F9: =IFERROR(Calculations!D3,"—") -> 38.4 | G9: =IFERROR(Calculations!E3,"—") -> 92.475556 | I9: Average | J9: =IFERROR(Calculations!F3,"—") -> 20.7 | K9: =IFERROR(Calculations!G3,"—") -> 77.814444 | M9: Average | N9: =IFERROR(Calculations!H3,"—") -> 20 | O9: =IFERROR(Calculations!I3,"—") -> 71.315556 | R9: Month | S9: Planned | T9: Done | U9: Pending | V9: % Done
A10: Median | B10: =IFERROR(Calculations!B4,"—") -> 82.5 | C10: =IFERROR(Calculations!C4,"—") -> 94.82 | E10: Median | F10: =IFERROR(Calculations!D4,"—") -> 37.5 | G10: =IFERROR(Calculations!E4,"—") -> 98.12 | I10: Median | J10: =IFERROR(Calculations!F4,"—") -> 22 | K10: =IFERROR(Calculations!G4,"—") -> 83.74 | M10: Median | N10: =IFERROR(Calculations!H4,"—") -> 20.5 | O10: =IFERROR(Calculations!I4,"—") -> 69.82 | R10: =IFERROR(EOMONTH(_xlfn.MINIFS('Mock Database'!$H$3:$H$152,'Mock Database'!$D$3:$D$152,"<>",'Mock Database'!$H$3:$H$152,">0"),-1)+1,"") -> 46113 | S10: =IF($R10="","",COUNTIFS('Mock Database'!$D$3:$D$152,"<>",'Mock Database'!$H$3:$H$152,">="&$R10,'Mock Database'!$H$3:$H$152,"<="&EOMONTH($R10,0))) -> 1 | T10: =IF($R10="","",COUNTIFS('Mock Database'!$D$3:$D$152,"<>",'Mock Database'!$H$3:$H$152,">="&$R10,'Mock Database'!$H$3:$H$152,"<="&EOMONTH($R10,0),'Mock Database'!$J$3:$J$152,"Completed")) -> 1 | U10: =IF($R10="","",$S10-$T10) -> 0 | V10: =IF($R10="","",IF($S10=0,"",$T10/$S10)) -> 1
A11: Highest | B11: =IFERROR(Calculations!B5,"—") -> 95 | C11: =IFERROR(Calculations!C5,"—") -> 98.37 | E11: Highest | F11: =IFERROR(Calculations!D5,"—") -> 50 | G11: =IFERROR(Calculations!E5,"—") -> 99.91 | I11: Highest | J11: =IFERROR(Calculations!F5,"—") -> 36 | K11: =IFERROR(Calculations!G5,"—") -> 94.69 | M11: Highest | N11: =IFERROR(Calculations!H5,"—") -> 36 | O11: =IFERROR(Calculations!I5,"—") -> 96.81 | R11: =IF($R10="","",IF(EOMONTH($R10,0)+1>_xlfn.MAXIFS('Mock Database'!$H$3:$H$152,'Mock Database'!$D$3:$D$152,"<>",'Mock Database'!$H$3:$H$152,">0"),"",EOMONTH($R10,0)+1)) -> 46143 | S11: =IF($R11="","",COUNTIFS('Mock Database'!$D$3:$D$152,"<>",'Mock Database'!$H$3:$H$152,">="&$R11,'Mock Database'!$H$3:$H$152,"<="&EOMONTH($R11,0))) -> 2 | T11: =IF($R11="","",COUNTIFS('Mock Database'!$D$3:$D$152,"<>",'Mock Database'!$H$3:$H$152,">="&$R11,'Mock Database'!$H$3:$H$152,"<="&EOMONTH($R11,0),'Mock Database'!$J$3:$J$152,"Completed")) -> 2 | U11: =IF($R11="","",$S11-$T11) -> 0 | V11: =IF($R11="","",IF($S11=0,"",$T11/$S11)) -> 1
A12: Lowest | B12: =IFERROR(Calculations!B6,"—") -> 55 | C12: =IFERROR(Calculations!C6,"—") -> 79.22 | E12: Lowest | F12: =IFERROR(Calculations!D6,"—") -> 20 | G12: =IFERROR(Calculations!E6,"—") -> 65.51 | I12: Lowest | J12: =IFERROR(Calculations!F6,"—") -> 3 | K12: =IFERROR(Calculations!G6,"—") -> 33.84 | M12: Lowest | N12: =IFERROR(Calculations!H6,"—") -> 10 | O12: =IFERROR(Calculations!I6,"—") -> 45.38 | R12: =IF($R11="","",IF(EOMONTH($R11,0)+1>_xlfn.MAXIFS('Mock Database'!$H$3:$H$152,'Mock Database'!$D$3:$D$152,"<>",'Mock Database'!$H$3:$H$152,">0"),"",EOMONTH($R11,0)+1)) -> 46174 | S12: =IF($R12="","",COUNTIFS('Mock Database'!$D$3:$D$152,"<>",'Mock Database'!$H$3:$H$152,">="&$R12,'Mock Database'!$H$3:$H$152,"<="&EOMONTH($R12,0))) -> 6 | T12: =IF($R12="","",COUNTIFS('Mock Database'!$D$3:$D$152,"<>",'Mock Database'!$H$3:$H$152,">="&$R12,'Mock Database'!$H$3:$H$152,"<="&EOMONTH($R12,0),'Mock Database'!$J$3:$J$152,"Completed")) -> 6 | U12: =IF($R12="","",$S12-$T12) -> 0 | V12: =IF($R12="","",IF($S12=0,"",$T12/$S12)) -> 1
A13: Std Dev | B13: =IFERROR(Calculations!B8,"—") -> 12.059574 | C13: =IFERROR(Calculations!C8,"—") -> 6.4978056 | E13: Std Dev | F13: =IFERROR(Calculations!D8,"—") -> 9.9129545 | G13: =IFERROR(Calculations!E8,"—") -> 11.02697 | I13: Std Dev | J13: =IFERROR(Calculations!F8,"—") -> 9.345825 | K13: =IFERROR(Calculations!G8,"—") -> 19.426395 | M13: Std Dev | N13: =IFERROR(Calculations!H8,"—") -> 7.8031333 | O13: =IFERROR(Calculations!I8,"—") -> 15.920514 | R13: =IF($R12="","",IF(EOMONTH($R12,0)+1>_xlfn.MAXIFS('Mock Database'!$H$3:$H$152,'Mock Database'!$D$3:$D$152,"<>",'Mock Database'!$H$3:$H$152,">0"),"",EOMONTH($R12,0)+1)) -> 46204 | S13: =IF($R13="","",COUNTIFS('Mock Database'!$D$3:$D$152,"<>",'Mock Database'!$H$3:$H$152,">="&$R13,'Mock Database'!$H$3:$H$152,"<="&EOMONTH($R13,0))) -> 11 | T13: =IF($R13="","",COUNTIFS('Mock Database'!$D$3:$D$152,"<>",'Mock Database'!$H$3:$H$152,">="&$R13,'Mock Database'!$H$3:$H$152,"<="&EOMONTH($R13,0),'Mock Database'!$J$3:$J$152,"Completed")) -> 1 | U13: =IF($R13="","",$S13-$T13) -> 10 | V13: =IF($R13="","",IF($S13=0,"",$T13/$S13)) -> 0.090909091
A14: Roll Avg 5 | B14: =IFERROR(Calculations!B9,"—") -> 75.8 | C14: =IFERROR(Calculations!C9,"—") -> 92.3775 | E14: Roll Avg 5 | F14: =IFERROR(Calculations!D9,"—") -> 37.2 | G14: =IFERROR(Calculations!E9,"—") -> 90.79 | I14: Roll Avg 5 | J14: =IFERROR(Calculations!F9,"—") -> 16.8 | K14: =IFERROR(Calculations!G9,"—") -> 67.3375 | M14: Roll Avg 5 | N14: =IFERROR(Calculations!H9,"—") -> 21.8 | O14: =IFERROR(Calculations!I9,"—") -> 73.785 | R14: =IF($R13="","",IF(EOMONTH($R13,0)+1>_xlfn.MAXIFS('Mock Database'!$H$3:$H$152,'Mock Database'!$D$3:$D$152,"<>",'Mock Database'!$H$3:$H$152,">0"),"",EOMONTH($R13,0)+1)) -> 46235 | S14: =IF($R14="","",COUNTIFS('Mock Database'!$D$3:$D$152,"<>",'Mock Database'!$H$3:$H$152,">="&$R14,'Mock Database'!$H$3:$H$152,"<="&EOMONTH($R14,0))) -> 19 | T14: =IF($R14="","",COUNTIFS('Mock Database'!$D$3:$D$152,"<>",'Mock Database'!$H$3:$H$152,">="&$R14,'Mock Database'!$H$3:$H$152,"<="&EOMONTH($R14,0),'Mock Database'!$J$3:$J$152,"Completed")) -> 0 | U14: =IF($R14="","",$S14-$T14) -> 19 | V14: =IF($R14="","",IF($S14=0,"",$T14/$S14)) -> 0
A15: Roll Avg 10 | B15: =IFERROR(Calculations!B10,"—") -> 79.1 | C15: =IFERROR(Calculations!C10,"—") -> 92.015556 | E15: Roll Avg 10 | F15: =IFERROR(Calculations!D10,"—") -> 38.4 | G15: =IFERROR(Calculations!E10,"—") -> 92.475556 | I15: Roll Avg 10 | J15: =IFERROR(Calculations!F10,"—") -> 20.7 | K15: =IFERROR(Calculations!G10,"—") -> 77.814444 | M15: Roll Avg 10 | N15: =IFERROR(Calculations!H10,"—") -> 20 | O15: =IFERROR(Calculations!I10,"—") -> 71.315556 | R15: =IF($R14="","",IF(EOMONTH($R14,0)+1>_xlfn.MAXIFS('Mock Database'!$H$3:$H$152,'Mock Database'!$D$3:$D$152,"<>",'Mock Database'!$H$3:$H$152,">0"),"",EOMONTH($R14,0)+1)) -> 46266 | S15: =IF($R15="","",COUNTIFS('Mock Database'!$D$3:$D$152,"<>",'Mock Database'!$H$3:$H$152,">="&$R15,'Mock Database'!$H$3:$H$152,"<="&EOMONTH($R15,0))) -> 13 | T15: =IF($R15="","",COUNTIFS('Mock Database'!$D$3:$D$152,"<>",'Mock Database'!$H$3:$H$152,">="&$R15,'Mock Database'!$H$3:$H$152,"<="&EOMONTH($R15,0),'Mock Database'!$J$3:$J$152,"Completed")) -> 0 | U15: =IF($R15="","",$S15-$T15) -> 13 | V15: =IF($R15="","",IF($S15=0,"",$T15/$S15)) -> 0
A16: Improvement | B16: =IFERROR(Calculations!B11,"—") -> -21 | C16: =IFERROR(Calculations!C11,"—") -> -9.7 | D16: =IFERROR(IF(Calculations!B11>=0,"▲","▼"),"—") -> ▼ | E16: Improvement | F16: =IFERROR(Calculations!D11,"—") -> -11 | G16: =IFERROR(Calculations!E11,"—") -> -22.51 | H16: =IFERROR(IF(Calculations!D11>=0,"▲","▼"),"—") -> ▼ | I16: Improvement | J16: =IFERROR(Calculations!F11,"—") -> -8 | K16: =IFERROR(Calculations!G11,"—") -> -6.3 | L16: =IFERROR(IF(Calculations!F11>=0,"▲","▼"),"—") -> ▼ | M16: Improvement | N16: =IFERROR(Calculations!H11,"—") -> -2 | O16: =IFERROR(Calculations!I11,"—") -> 0.01 | P16: =IFERROR(IF(Calculations!H11>=0,"▲","▼"),"—") -> ▼ | R16: =IF($R15="","",IF(EOMONTH($R15,0)+1>_xlfn.MAXIFS('Mock Database'!$H$3:$H$152,'Mock Database'!$D$3:$D$152,"<>",'Mock Database'!$H$3:$H$152,">0"),"",EOMONTH($R15,0)+1)) -> 46296 | S16: =IF($R16="","",COUNTIFS('Mock Database'!$D$3:$D$152,"<>",'Mock Database'!$H$3:$H$152,">="&$R16,'Mock Database'!$H$3:$H$152,"<="&EOMONTH($R16,0))) -> 25 | T16: =IF($R16="","",COUNTIFS('Mock Database'!$D$3:$D$152,"<>",'Mock Database'!$H$3:$H$152,">="&$R16,'Mock Database'!$H$3:$H$152,"<="&EOMONTH($R16,0),'Mock Database'!$J$3:$J$152,"Completed")) -> 0 | U16: =IF($R16="","",$S16-$T16) -> 25 | V16: =IF($R16="","",IF($S16=0,"",$T16/$S16)) -> 0
A17: Trend / mock | B17: =IFERROR(Calculations!B32,"—") -> -1.5212121 | C17: =IFERROR(Calculations!C32,"—") -> -0.41654839 | D17: =IFERROR(IF(Calculations!B32>=0,"▲","▼"),"—") -> ▼ | E17: Trend / mock | F17: =IFERROR(Calculations!D32,"—") -> -0.83636364 | G17: =IFERROR(Calculations!E32,"—") -> -1.3071129 | H17: =IFERROR(IF(Calculations!D32>=0,"▲","▼"),"—") -> ▼ | I17: Trend / mock | J17: =IFERROR(Calculations!F32,"—") -> -1.2181818 | K17: =IFERROR(Calculations!G32,"—") -> -2.5792903 | L17: =IFERROR(IF(Calculations!F32>=0,"▲","▼"),"—") -> ▼ | M17: Trend / mock | N17: =IFERROR(Calculations!H32,"—") -> 0.53333333 | O17: =IFERROR(Calculations!I32,"—") -> 0.66185484 | P17: =IFERROR(IF(Calculations!H32>=0,"▲","▼"),"—") -> ▲ | R17: =IF($R16="","",IF(EOMONTH($R16,0)+1>_xlfn.MAXIFS('Mock Database'!$H$3:$H$152,'Mock Database'!$D$3:$D$152,"<>",'Mock Database'!$H$3:$H$152,">0"),"",EOMONTH($R16,0)+1)) -> 46327 | S17: =IF($R17="","",COUNTIFS('Mock Database'!$D$3:$D$152,"<>",'Mock Database'!$H$3:$H$152,">="&$R17,'Mock Database'!$H$3:$H$152,"<="&EOMONTH($R17,0))) -> 23 | T17: =IF($R17="","",COUNTIFS('Mock Database'!$D$3:$D$152,"<>",'Mock Database'!$H$3:$H$152,">="&$R17,'Mock Database'!$H$3:$H$152,"<="&EOMONTH($R17,0),'Mock Database'!$J$3:$J$152,"Completed")) -> 0 | U17: =IF($R17="","",$S17-$T17) -> 23 | V17: =IF($R17="","",IF($S17=0,"",$T17/$S17)) -> 0
A18: Consistency | B18: =IFERROR(Calculations!B16,"—") -> 84.754015 | C18: =IFERROR(Calculations!C16,"—") -> 92.938362 | D18: =IFERROR(IF(Calculations!B16>=90,"●●●",IF(Calculations!B16>=75,"●●○","●○○")),"—") -> ●●○ | E18: Consistency | F18: =IFERROR(Calculations!D16,"—") -> 74.185014 | G18: =IFERROR(Calculations!E16,"—") -> 88.0758 | H18: =IFERROR(IF(Calculations!D16>=90,"●●●",IF(Calculations!D16>=75,"●●○","●○○")),"—") -> ●○○ | I18: Consistency | J18: =IFERROR(Calculations!F16,"—") -> 54.851087 | K18: =IFERROR(Calculations!G16,"—") -> 75.034975 | L18: =IFERROR(IF(Calculations!F16>=90,"●●●",IF(Calculations!F16>=75,"●●○","●○○")),"—") -> ●○○ | M18: Consistency | N18: =IFERROR(Calculations!H16,"—") -> 60.984334 | O18: =IFERROR(Calculations!I16,"—") -> 77.675959 | P18: =IFERROR(IF(Calculations!H16>=90,"●●●",IF(Calculations!H16>=75,"●●○","●○○")),"—") -> ●○○ | R18: =IF($R17="","",IF(EOMONTH($R17,0)+1>_xlfn.MAXIFS('Mock Database'!$H$3:$H$152,'Mock Database'!$D$3:$D$152,"<>",'Mock Database'!$H$3:$H$152,">0"),"",EOMONTH($R17,0)+1)) | S18: =IF($R18="","",COUNTIFS('Mock Database'!$D$3:$D$152,"<>",'Mock Database'!$H$3:$H$152,">="&$R18,'Mock Database'!$H$3:$H$152,"<="&EOMONTH($R18,0))) | T18: =IF($R18="","",COUNTIFS('Mock Database'!$D$3:$D$152,"<>",'Mock Database'!$H$3:$H$152,">="&$R18,'Mock Database'!$H$3:$H$152,"<="&EOMONTH($R18,0),'Mock Database'!$J$3:$J$152,"Completed")) | U18: =IF($R18="","",$S18-$T18) | V18: =IF($R18="","",IF($S18=0,"",$T18/$S18))
A19: =IFERROR(" ◈ Strongest: "&Calculations!B18&" · Weakest: "&Calculations!B19&" · Most Improved: "&Calculations!B20," Enter scores to see section insights") -> ◈ Strongest: VARC · Weakest: QA · Most Improved: QA | I19: =IFERROR(" ◈ Projected next overall: "&ROUND(Calculations!B33,0)&" · Trend "&TEXT(Calculations!B32,"+0.0;-0.0")&" pts/mock · Target "&TEXT(Calculations!B38,"0.0")&" %ile: "&Calculations!E38&" · GP Avg (r="&TEXT(Calculations!B42,"0.000")&"): "&TEXT(Calculations!B35,"0.0")," —") -> ◈ Projected next overall: 71 · Trend -1.5 pts/mock · Target 99.9 %ile: Behind · GP Avg (r=0.945): 78.4 | R19: Total | S19: =SUM($S$10:$S$18) -> 100 | T19: =SUM($T$10:$T$18) -> 10 | U19: =SUM($U$10:$U$18) -> 90 | V19: =IF($S$19=0,"",$T$19/$S$19) -> 0.1
A21: 📊 Preparation Progress
A22: =TEXT(Calculations!B25,"0.0%") -> 10.0% | E22: =TEXT(Calculations!B28,"0.0%") -> 100.0% | I22: =Calculations!B24 -> 90 | M22: =Calculations!B27 -> 0
A23: COMPLETION RATE | E23: ANALYSIS RATE | I23: REMAINING MOCKS | M23: ANALYSIS PENDING
A25: 📈 Performance Charts — Auto-update as scores are entered · 150 rows pre-created | R25: 🔎 Mock Index — every graphed metric, by attempt #
A26: ★ Made by Devansh Gohil · CAT 2026 Analytics · Formula-driven · Excel & Google Sheets compatible · 150 mock rows pre-created | R26: Mock | U26: VARC | W26: DILR | Y26: QA | AA26: Overall
R27: # | S27: Mock | T27: Date | U27: Score | V27: %ile | W27: Score | X27: %ile | Y27: Score | Z27: %ile | AA27: Score | AB27: %ile
R28: {=_xlfn._xlws.FILTER(Chart_Data!$A$2:$A$401,Chart_Data!$B$2:$B$401<>"","")} -> 1 | S28: {=_xlfn._xlws.FILTER(Chart_Data!$B$2:$B$401,Chart_Data!$B$2:$B$401<>"","")} -> SimCAT 1 | T28: {=_xlfn._xlws.FILTER(Chart_Data!$C$2:$C$401,Chart_Data!$B$2:$B$401<>"","")} -> 46137 | U28: {=_xlfn._xlws.FILTER(Chart_Data!$D$2:$D$401,Chart_Data!$B$2:$B$401<>"","")} -> 31 | V28: {=_xlfn._xlws.FILTER(Chart_Data!$E$2:$E$401,Chart_Data!$B$2:$B$401<>"","")} -> 88.02 | W28: {=_xlfn._xlws.FILTER(Chart_Data!$F$2:$F$401,Chart_Data!$B$2:$B$401<>"","")} -> 24 | X28: {=_xlfn._xlws.FILTER(Chart_Data!$G$2:$G$401,Chart_Data!$B$2:$B$401<>"","")} -> 90.04 | Y28: {=_xlfn._xlws.FILTER(Chart_Data!$H$2:$H$401,Chart_Data!$B$2:$B$401<>"","")} -> 21 | Z28: {=_xlfn._xlws.FILTER(Chart_Data!$I$2:$I$401,Chart_Data!$B$2:$B$401<>"","")} -> 69.81 | AA28: {=_xlfn._xlws.FILTER(Chart_Data!$J$2:$J$401,Chart_Data!$B$2:$B$401<>"","")} -> 76 | AB28: {=_xlfn._xlws.FILTER(Chart_Data!$K$2:$K$401,Chart_Data!$B$2:$B$401<>"","")} -> 88.92
R29: 2 | S29: SimCAT 2 | T29: 46172 | U29: 35 | V29: 92.72 | W29: 36 | X29: 94.69 | Y29: 24 | Z29: 85.41 | AA29: 95 | AB29: 94.98
R30: 3 | S30: SimCAT 3 | T30: 46173 | U30: 49 | V30: 99.09 | W30: 21 | X30: 91.49 | Y30: 13 | Z30: 62.2 | AA30: 83 | AB30: 95.61
R31: 4 | S31: Take Home 1 | T31: 46179 | U31: 34 | V31: 90.5 | W31: 13 | X31: 62.87 | Y31: 23 | Z31: 74.39 | AA31: 70 | AB31: 84.3
R32: 5 | S32: SimCAT 4 | T32: 46186 | U32: 49 | V32: 98.79 | W32: 29 | X32: 91.89 | Y32: 10 | Z32: 54.89 | AA32: 88 | AB32: 94.82
R33: 6 | S33: Take Home 2 | T33: 46191 | U33: 50 | V33: 99.62 | W33: 23 | X33: 75.74 | Y33: 10 | Z33: 45.38 | AA33: 83 | AB33: 94.57
R34: 7 | S34: Take Home 3 | T34: 46198 | U34: 45 | V34: 99.91 | W34: 3 | X34: 33.84 | Y34: 20 | Z34: 83.13 | AA34: 68 | AB34: 98.37
R35: 8 | S35: SimCAT 5 | T35: 46201 | U35: 40 | V35: 98.12 | W35: 15 | X35: 76.03 | Y35: 36 | Z35: 96.81 | AA35: 91 | AB35: 97.35
R36: 9 | S36: CAT 2021 Slot 1 | T36: 46204 | U36: 31 | W36: 27 | Y36: 24 | AA36: 82
R37: 10 | S37: Take Home 4 | T37: 46216 | U37: 20 | V37: 65.51 | W37: 16 | X37: 83.74 | Y37: 19 | Z37: 69.82 | AA37: 55 | AB37: 79.22

Sheet Lists
A1: Providers | B1: Series | C1: MockTypes | D1: AnalysisDone
A2: IMS | B2: SimCAT | C2: Proctored | D2: Yes
A3: Cracku | B3: Take Home | C3: Take Home | D3: No
A4: Arun Sharma | B4: Previous CAT | C4: Past CAT Paper
A5: TIME | B5: DashCAT
A6: Career Launcher | B6: Headstart CAT
A7: Rodha | B7: Others
A8: Others

Sheet Mock Database
A1: CAT 2026 — Mock Database | Single Source of Truth | Made by Devansh Gohil
A2: Mock No | B2: Planned Order | C2: Attempt Order | D2: Test Name | E2: Provider | F2: Series | G2: Mock Type | H2: Planned Date | I2: Actual Date | J2: Status | K2: Analysis Done | L2: Notes | M2: VARC Score | N2: VARC %ile | O2: VARC Attempts | P2: VARC Correct | Q2: VARC Incorrect | R2: VARC Accuracy | S2: DILR Score | T2: DILR %ile | U2: DILR Attempts | V2: DILR Correct | W2: DILR Incorrect | X2: DILR Accuracy | Y2: QA Score | Z2: QA %ile | AA2: QA Attempts | AB2: QA Correct | AC2: QA Incorrect | AD2: QA Accuracy | AE2: Ovr Score | AF2: Ovr %ile | AG2: Ovr Attempts | AH2: Ovr Correct | AI2: Ovr Incorrect | AJ2: Ovr Accuracy
A3: 1 | B3: =IFERROR(IF(H3<>"",RANK(H3,$H$3:$H$400,1),""),"") -> 1 | C3: =IFERROR(IF(J3="Completed",COUNTIFS(J$3:J$400,"Completed",I$3:I$400,"<"&I3,I$3:I$400,"<>"&"")+COUNTIFS(J$3:J$400,"Completed",I$3:I$400,"="&I3,A$3:A$400,"<="&A3,I$3:I$400,"<>"&""),""),"") -> 1 | D3: SimCAT 1 | E3: IMS | F3: SimCAT | G3: Proctored | H3: 46137 | I3: 46137 | J3: =IF(I3<>"","Completed","Pending") -> Completed | K3: Yes | M3: 31 | N3: 88.02 | O3: 24 | P3: 13 | Q3: =IF(COUNT(O3,P3)=2, O3-P3, "") -> 11 | R3: =IFERROR(P3/O3,"") -> 0.54166667 | S3: 24 | T3: 90.04 | U3: 11 | V3: 8 | W3: =IF(COUNT(U3,V3)=2, U3-V3, "") -> 3 | X3: =IFERROR(V3/U3,"") -> 0.72727273 | Y3: 21 | Z3: 69.81 | AA3: 9 | AB3: 7 | AC3: =IF(COUNT(AA3,AB3)=2, AA3-AB3, "") -> 2 | AD3: =IFERROR(AB3/AA3,"") -> 0.77777778 | AE3: =IF(AND(M3="",S3="",Y3=""),"",IFERROR(M3+S3+Y3,"")) -> 76 | AF3: 88.92 | AG3: =IF(AND(O3="",U3="",AA3=""),"",IFERROR(O3+U3+AA3,"")) -> 44 | AH3: =IF(AND(P3="",V3="",AB3=""),"",IFERROR(P3+V3+AB3,"")) -> 28 | AI3: =IF(AND(Q3="",W3="",AC3=""),"",IFERROR(Q3+W3+AC3,"")) -> 16 | AJ3: =IFERROR(AH3/AG3,"") -> 0.63636364
A4: 2 | B4: =IFERROR(IF(H4<>"",RANK(H4,$H$3:$H$400,1),""),"") -> 2 | C4: =IFERROR(IF(J4="Completed",COUNTIFS(J$3:J$400,"Completed",I$3:I$400,"<"&I4,I$3:I$400,"<>"&"")+COUNTIFS(J$3:J$400,"Completed",I$3:I$400,"="&I4,A$3:A$400,"<="&A4,I$3:I$400,"<>"&""),""),"") -> 2 | D4: SimCAT 2 | E4: IMS | F4: SimCAT | G4: Proctored | H4: 46172 | I4: 46172 | J4: =IF(I4<>"","Completed","Pending") -> Completed | K4: Yes | M4: 35 | N4: 92.72 | O4: 24 | P4: 14 | Q4: =IF(COUNT(O4,P4)=2, O4-P4, "") -> 10 | R4: =IFERROR(P4/O4,"") -> 0.58333333 | S4: 36 | T4: 94.69 | U4: 12 | V4: 12 | W4: =IF(COUNT(U4,V4)=2, U4-V4, "") -> 0 | X4: =IFERROR(V4/U4,"") -> 1 | Y4: 24 | Z4: 85.41 | AA4: 8 | AB4: 8 | AC4: =IF(COUNT(AA4,AB4)=2, AA4-AB4, "") -> 0 | AD4: =IFERROR(AB4/AA4,"") -> 1 | AE4: =IF(AND(M4="",S4="",Y4=""),"",IFERROR(M4+S4+Y4,"")) -> 95 | AF4: 94.98 | AG4: =IF(AND(O4="",U4="",AA4=""),"",IFERROR(O4+U4+AA4,"")) -> 44 | AH4: =IF(AND(P4="",V4="",AB4=""),"",IFERROR(P4+V4+AB4,"")) -> 34 | AI4: =IF(AND(Q4="",W4="",AC4=""),"",IFERROR(Q4+W4+AC4,"")) -> 10 | AJ4: =IFERROR(AH4/AG4,"") -> 0.77272727
A5: 3 | B5: =IFERROR(IF(H5<>"",RANK(H5,$H$3:$H$400,1),""),"") -> 3 | C5: =IFERROR(IF(J5="Completed",COUNTIFS(J$3:J$400,"Completed",I$3:I$400,"<"&I5,I$3:I$400,"<>"&"")+COUNTIFS(J$3:J$400,"Completed",I$3:I$400,"="&I5,A$3:A$400,"<="&A5,I$3:I$400,"<>"&""),""),"") -> 3 | D5: SimCAT 3 | E5: IMS | F5: SimCAT | G5: Proctored | H5: 46173 | I5: 46173 | J5: =IF(I5<>"","Completed","Pending") -> Completed | K5: Yes | M5: 49 | N5: 99.09 | O5: 24 | P5: 18 | Q5: =IF(COUNT(O5,P5)=2, O5-P5, "") -> 6 | R5: =IFERROR(P5/O5,"") -> 0.75 | S5: 21 | T5: 91.49 | U5: 9 | V5: 7 | W5: =IF(COUNT(U5,V5)=2, U5-V5, "") -> 2 | X5: =IFERROR(V5/U5,"") -> 0.77777778 | Y5: 13 | Z5: 62.2 | AA5: 8 | AB5: 5 | AC5: =IF(COUNT(AA5,AB5)=2, AA5-AB5, "") -> 3 | AD5: =IFERROR(AB5/AA5,"") -> 0.625 | AE5: =IF(AND(M5="",S5="",Y5=""),"",IFERROR(M5+S5+Y5,"")) -> 83 | AF5: 95.61 | AG5: =IF(AND(O5="",U5="",AA5=""),"",IFERROR(O5+U5+AA5,"")) -> 41 | AH5: =IF(AND(P5="",V5="",AB5=""),"",IFERROR(P5+V5+AB5,"")) -> 30 | AI5: =IF(AND(Q5="",W5="",AC5=""),"",IFERROR(Q5+W5+AC5,"")) -> 11 | AJ5: =IFERROR(AH5/AG5,"") -> 0.73170732
A6: 4 | B6: =IFERROR(IF(H6<>"",RANK(H6,$H$3:$H$400,1),""),"") -> 4 | C6: =IFERROR(IF(J6="Completed",COUNTIFS(J$3:J$400,"Completed",I$3:I$400,"<"&I6,I$3:I$400,"<>"&"")+COUNTIFS(J$3:J$400,"Completed",I$3:I$400,"="&I6,A$3:A$400,"<="&A6,I$3:I$400,"<>"&""),""),"") -> 4 | D6: Take Home 1 | E6: IMS | F6: Take Home | G6: Take Home | H6: 46179 | I6: 46179 | J6: =IF(I6<>"","Completed","Pending") -> Completed | K6: Yes | M6: 34 | N6: 90.5 | O6: 24 | P6: 14 | Q6: =IF(COUNT(O6,P6)=2, O6-P6, "") -> 10 | R6: =IFERROR(P6/O6,"") -> 0.58333333 | S6: 13 | T6: 62.87 | U6: 8 | V6: 5 | W6: =IF(COUNT(U6,V6)=2, U6-V6, "") -> 3 | X6: =IFERROR(V6/U6,"") -> 0.625 | Y6: 23 | Z6: 74.39 | AA6: 9 | AB6: 8 | AC6: =IF(COUNT(AA6,AB6)=2, AA6-AB6, "") -> 1 | AD6: =IFERROR(AB6/AA6,"") -> 0.88888889 | AE6: =IF(AND(M6="",S6="",Y6=""),"",IFERROR(M6+S6+Y6,"")) -> 70 | AF6: 84.3 | AG6: =IF(AND(O6="",U6="",AA6=""),"",IFERROR(O6+U6+AA6,"")) -> 41 | AH6: =IF(AND(P6="",V6="",AB6=""),"",IFERROR(P6+V6+AB6,"")) -> 27 | AI6: =IF(AND(Q6="",W6="",AC6=""),"",IFERROR(Q6+W6+AC6,"")) -> 14 | AJ6: =IFERROR(AH6/AG6,"") -> 0.65853659
A7: 5 | B7: =IFERROR(IF(H7<>"",RANK(H7,$H$3:$H$400,1),""),"") -> 5 | C7: =IFERROR(IF(J7="Completed",COUNTIFS(J$3:J$400,"Completed",I$3:I$400,"<"&I7,I$3:I$400,"<>"&"")+COUNTIFS(J$3:J$400,"Completed",I$3:I$400,"="&I7,A$3:A$400,"<="&A7,I$3:I$400,"<>"&""),""),"") -> 5 | D7: SimCAT 4 | E7: IMS | F7: SimCAT | G7: Proctored | H7: 46186 | I7: 46186 | J7: =IF(I7<>"","Completed","Pending") -> Completed | K7: Yes | M7: 49 | N7: 98.79 | O7: 24 | P7: 18 | Q7: =IF(COUNT(O7,P7)=2, O7-P7, "") -> 6 | R7: =IFERROR(P7/O7,"") -> 0.75 | S7: 29 | T7: 91.89 | U7: 12 | V7: 10 | W7: =IF(COUNT(U7,V7)=2, U7-V7, "") -> 2 | X7: =IFERROR(V7/U7,"") -> 0.83333333 | Y7: 10 | Z7: 54.89 | AA7: 10 | AB7: 4 | AC7: =IF(COUNT(AA7,AB7)=2, AA7-AB7, "") -> 6 | AD7: =IFERROR(AB7/AA7,"") -> 0.4 | AE7: =IF(AND(M7="",S7="",Y7=""),"",IFERROR(M7+S7+Y7,"")) -> 88 | AF7: 94.82 | AG7: =IF(AND(O7="",U7="",AA7=""),"",IFERROR(O7+U7+AA7,"")) -> 46 | AH7: =IF(AND(P7="",V7="",AB7=""),"",IFERROR(P7+V7+AB7,"")) -> 32 | AI7: =IF(AND(Q7="",W7="",AC7=""),"",IFERROR(Q7+W7+AC7,"")) -> 14 | AJ7: =IFERROR(AH7/AG7,"") -> 0.69565217
A8: 6 | B8: =IFERROR(IF(H8<>"",RANK(H8,$H$3:$H$400,1),""),"") -> 6 | C8: =IFERROR(IF(J8="Completed",COUNTIFS(J$3:J$400,"Completed",I$3:I$400,"<"&I8,I$3:I$400,"<>"&"")+COUNTIFS(J$3:J$400,"Completed",I$3:I$400,"="&I8,A$3:A$400,"<="&A8,I$3:I$400,"<>"&""),""),"") -> 6 | D8: Take Home 2 | E8: IMS | F8: Take Home | G8: Take Home | H8: 46191 | I8: 46191 | J8: =IF(I8<>"","Completed","Pending") -> Completed | K8: Yes | M8: 50 | N8: 99.62 | O8: 24 | P8: 18 | Q8: =IF(COUNT(O8,P8)=2, O8-P8, "") -> 6 | R8: =IFERROR(P8/O8,"") -> 0.75 | S8: 23 | T8: 75.74 | U8: 9 | V8: 8 | W8: =IF(COUNT(U8,V8)=2, U8-V8, "") -> 1 | X8: =IFERROR(V8/U8,"") -> 0.88888889 | Y8: 10 | Z8: 45.38 | AA8: 10 | AB8: 4 | AC8: =IF(COUNT(AA8,AB8)=2, AA8-AB8, "") -> 6 | AD8: =IFERROR(AB8/AA8,"") -> 0.4 | AE8: =IF(AND(M8="",S8="",Y8=""),"",IFERROR(M8+S8+Y8,"")) -> 83 | AF8: 94.57 | AG8: =IF(AND(O8="",U8="",AA8=""),"",IFERROR(O8+U8+AA8,"")) -> 43 | AH8: =IF(AND(P8="",V8="",AB8=""),"",IFERROR(P8+V8+AB8,"")) -> 30 | AI8: =IF(AND(Q8="",W8="",AC8=""),"",IFERROR(Q8+W8+AC8,"")) -> 13 | AJ8: =IFERROR(AH8/AG8,"") -> 0.69767442
A9: 7 | B9: =IFERROR(IF(H9<>"",RANK(H9,$H$3:$H$400,1),""),"") -> 7 | C9: =IFERROR(IF(J9="Completed",COUNTIFS(J$3:J$400,"Completed",I$3:I$400,"<"&I9,I$3:I$400,"<>"&"")+COUNTIFS(J$3:J$400,"Completed",I$3:I$400,"="&I9,A$3:A$400,"<="&A9,I$3:I$400,"<>"&""),""),"") -> 9 | D9: CAT 2021 Slot 1 | E9: IMS | F9: Previous CAT | G9: Past CAT Paper | H9: 46193 | I9: 46204 | J9: =IF(I9<>"","Completed","Pending") -> Completed | K9: Yes | M9: 31 | O9: 24 | P9: 14 | Q9: =IF(COUNT(O9,P9)=2, O9-P9, "") -> 10 | R9: =IFERROR(P9/O9,"") -> 0.58333333 | S9: 27 | U9: 12 | V9: 9 | W9: =IF(COUNT(U9,V9)=2, U9-V9, "") -> 3 | X9: =IFERROR(V9/U9,"") -> 0.75 | Y9: 24 | AA9: 14 | AB9: 8 | AC9: =IF(COUNT(AA9,AB9)=2, AA9-AB9, "") -> 6 | AD9: =IFERROR(AB9/AA9,"") -> 0.57142857 | AE9: =IF(AND(M9="",S9="",Y9=""),"",IFERROR(M9+S9+Y9,"")) -> 82 | AG9: =IF(AND(O9="",U9="",AA9=""),"",IFERROR(O9+U9+AA9,"")) -> 50 | AH9: =IF(AND(P9="",V9="",AB9=""),"",IFERROR(P9+V9+AB9,"")) -> 31 | AI9: =IF(AND(Q9="",W9="",AC9=""),"",IFERROR(Q9+W9+AC9,"")) -> 19 | AJ9: =IFERROR(AH9/AG9,"") -> 0.62
A10: 8 | B10: =IFERROR(IF(H10<>"",RANK(H10,$H$3:$H$400,1),""),"") -> 8 | C10: =IFERROR(IF(J10="Completed",COUNTIFS(J$3:J$400,"Completed",I$3:I$400,"<"&I10,I$3:I$400,"<>"&"")+COUNTIFS(J$3:J$400,"Completed",I$3:I$400,"="&I10,A$3:A$400,"<="&A10,I$3:I$400,"<>"&""),""),"") -> 7 | D10: Take Home 3 | E10: IMS | F10: Take Home | G10: Take Home | H10: 46198 | I10: 46198 | J10: =IF(I10<>"","Completed","Pending") -> Completed | K10: Yes | M10: 45 | N10: 99.91 | O10: 24 | P10: 17 | Q10: =IF(COUNT(O10,P10)=2, O10-P10, "") -> 7 | R10: =IFERROR(P10/O10,"") -> 0.70833333 | S10: 3 | T10: 33.84 | U10: 9 | V10: 2 | W10: =IF(COUNT(U10,V10)=2, U10-V10, "") -> 7 | X10: =IFERROR(V10/U10,"") -> 0.22222222 | Y10: 20 | Z10: 83.13 | AA10: 13 | AB10: 7 | AC10: =IF(COUNT(AA10,AB10)=2, AA10-AB10, "") -> 6 | AD10: =IFERROR(AB10/AA10,"") -> 0.53846154 | AE10: =IF(AND(M10="",S10="",Y10=""),"",IFERROR(M10+S10+Y10,"")) -> 68 | AF10: 98.37 | AG10: =IF(AND(O10="",U10="",AA10=""),"",IFERROR(O10+U10+AA10,"")) -> 46 | AH10: =IF(AND(P10="",V10="",AB10=""),"",IFERROR(P10+V10+AB10,"")) -> 26 | AI10: =IF(AND(Q10="",W10="",AC10=""),"",IFERROR(Q10+W10+AC10,"")) -> 20 | AJ10: =IFERROR(AH10/AG10,"") -> 0.56521739
A11: 9 | B11: =IFERROR(IF(H11<>"",RANK(H11,$H$3:$H$400,1),""),"") -> 9 | C11: =IFERROR(IF(J11="Completed",COUNTIFS(J$3:J$400,"Completed",I$3:I$400,"<"&I11,I$3:I$400,"<>"&"")+COUNTIFS(J$3:J$400,"Completed",I$3:I$400,"="&I11,A$3:A$400,"<="&A11,I$3:I$400,"<>"&""),""),"") -> 8 | D11: SimCAT 5 | E11: IMS | F11: SimCAT | G11: Proctored | H11: 46201 | I11: 46201 | J11: =IF(I11<>"","Completed","Pending") -> Completed | K11: Yes | M11: 40 | N11: 98.12 | O11: 24 | P11: 15 | Q11: =IF(COUNT(O11,P11)=2, O11-P11, "") -> 9 | R11: =IFERROR(P11/O11,"") -> 0.625 | S11: 15 | T11: 76.03 | U11: 15 | V11: 6 | W11: =IF(COUNT(U11,V11)=2, U11-V11, "") -> 9 | X11: =IFERROR(V11/U11,"") -> 0.4 | Y11: 36 | Z11: 96.81 | AA11: 15 | AB11: 12 | AC11: =IF(COUNT(AA11,AB11)=2, AA11-AB11, "") -> 3 | AD11: =IFERROR(AB11/AA11,"") -> 0.8 | AE11: =IF(AND(M11="",S11="",Y11=""),"",IFERROR(M11+S11+Y11,"")) -> 91 | AF11: 97.35 | AG11: =IF(AND(O11="",U11="",AA11=""),"",IFERROR(O11+U11+AA11,"")) -> 54 | AH11: =IF(AND(P11="",V11="",AB11=""),"",IFERROR(P11+V11+AB11,"")) -> 33 | AI11: =IF(AND(Q11="",W11="",AC11=""),"",IFERROR(Q11+W11+AC11,"")) -> 21 | AJ11: =IFERROR(AH11/AG11,"") -> 0.61111111
A12: 10 | B12: =IFERROR(IF(H12<>"",RANK(H12,$H$3:$H$400,1),""),"") -> 10 | C12: =IFERROR(IF(J12="Completed",COUNTIFS(J$3:J$400,"Completed",I$3:I$400,"<"&I12,I$3:I$400,"<>"&"")+COUNTIFS(J$3:J$400,"Completed",I$3:I$400,"="&I12,A$3:A$400,"<="&A12,I$3:I$400,"<>"&""),""),"") -> 10 | D12: Take Home 4 | E12: IMS | F12: Take Home | G12: Take Home | H12: 46207 | I12: 46216 | J12: =IF(I12<>"","Completed","Pending") -> Completed | K12: Yes | M12: 20 | N12: 65.51 | O12: 24 | P12: 10 | Q12: =IF(COUNT(O12,P12)=2, O12-P12, "") -> 14 | R12: =IFERROR(P12/O12,"") -> 0.41666667 | S12: 16 | T12: 83.74 | U12: 13 | V12: 6 | W12: =IF(COUNT(U12,V12)=2, U12-V12, "") -> 7 | X12: =IFERROR(V12/U12,"") -> 0.46153846 | Y12: 19 | Z12: 69.82 | AA12: 13 | AB12: 7 | AC12: =IF(COUNT(AA12,AB12)=2, AA12-AB12, "") -> 6 | AD12: =IFERROR(AB12/AA12,"") -> 0.53846154 | AE12: =IF(AND(M12="",S12="",Y12=""),"",IFERROR(M12+S12+Y12,"")) -> 55 | AF12: 79.22 | AG12: =IF(AND(O12="",U12="",AA12=""),"",IFERROR(O12+U12+AA12,"")) -> 50 | AH12: =IF(AND(P12="",V12="",AB12=""),"",IFERROR(P12+V12+AB12,"")) -> 23 | AI12: =IF(AND(Q12="",W12="",AC12=""),"",IFERROR(Q12+W12+AC12,"")) -> 27 | AJ12: =IFERROR(AH12/AG12,"") -> 0.46
A13: 11 | B13: =IFERROR(IF(H13<>"",RANK(H13,$H$3:$H$400,1),""),"") -> 11 | C13: =IFERROR(IF(J13="Completed",COUNTIFS(J$3:J$400,"Completed",I$3:I$400,"<"&I13,I$3:I$400,"<>"&"")+COUNTIFS(J$3:J$400,"Completed",I$3:I$400,"="&I13,A$3:A$400,"<="&A13,I$3:I$400,"<>"&""),""),"") | D13: CAT 2021 Slot 2 | E13: IMS | F13: Previous CAT | G13: Past CAT Paper | H13: 46211 | J13: =IF(I13<>"","Completed","Pending") -> Pending | K13: No | Q13: =IF(COUNT(O13,P13)=2, O13-P13, "") | R13: =IFERROR(P13/O13,"") | W13: =IF(COUNT(U13,V13)=2, U13-V13, "") | X13: =IFERROR(V13/U13,"") | AC13: =IF(COUNT(AA13,AB13)=2, AA13-AB13, "") | AD13: =IFERROR(AB13/AA13,"") | AE13: =IF(AND(M13="",S13="",Y13=""),"",IFERROR(M13+S13+Y13,"")) | AG13: =IF(AND(O13="",U13="",AA13=""),"",IFERROR(O13+U13+AA13,"")) | AH13: =IF(AND(P13="",V13="",AB13=""),"",IFERROR(P13+V13+AB13,"")) | AI13: =IF(AND(Q13="",W13="",AC13=""),"",IFERROR(Q13+W13+AC13,"")) | AJ13: =IFERROR(AH13/AG13,"")
A14: 12 | B14: =IFERROR(IF(H14<>"",RANK(H14,$H$3:$H$400,1),""),"") -> 12 | C14: =IFERROR(IF(J14="Completed",COUNTIFS(J$3:J$400,"Completed",I$3:I$400,"<"&I14,I$3:I$400,"<>"&"")+COUNTIFS(J$3:J$400,"Completed",I$3:I$400,"="&I14,A$3:A$400,"<="&A14,I$3:I$400,"<>"&""),""),"") | D14: SimCAT 6 | E14: IMS | F14: SimCAT | G14: Proctored | H14: 46213 | J14: =IF(I14<>"","Completed","Pending") -> Pending | K14: No | Q14: =IF(COUNT(O14,P14)=2, O14-P14, "") | R14: =IFERROR(P14/O14,"") | W14: =IF(COUNT(U14,V14)=2, U14-V14, "") | X14: =IFERROR(V14/U14,"") | AC14: =IF(COUNT(AA14,AB14)=2, AA14-AB14, "") | AD14: =IFERROR(AB14/AA14,"") | AE14: =IF(AND(M14="",S14="",Y14=""),"",IFERROR(M14+S14+Y14,"")) | AG14: =IF(AND(O14="",U14="",AA14=""),"",IFERROR(O14+U14+AA14,"")) | AH14: =IF(AND(P14="",V14="",AB14=""),"",IFERROR(P14+V14+AB14,"")) | AI14: =IF(AND(Q14="",W14="",AC14=""),"",IFERROR(Q14+W14+AC14,"")) | AJ14: =IFERROR(AH14/AG14,"")
A15: 13 | B15: =IFERROR(IF(H15<>"",RANK(H15,$H$3:$H$400,1),""),"") -> 13 | C15: =IFERROR(IF(J15="Completed",COUNTIFS(J$3:J$400,"Completed",I$3:I$400,"<"&I15,I$3:I$400,"<>"&"")+COUNTIFS(J$3:J$400,"Completed",I$3:I$400,"="&I15,A$3:A$400,"<="&A15,I$3:I$400,"<>"&""),""),"") | D15: Take Home 5 | E15: IMS | F15: Take Home | G15: Take Home | H15: 46218 | J15: =IF(I15<>"","Completed","Pending") -> Pending | K15: No | Q15: =IF(COUNT(O15,P15)=2, O15-P15, "") | R15: =IFERROR(P15/O15,"") | W15: =IF(COUNT(U15,V15)=2, U15-V15, "") | X15: =IFERROR(V15/U15,"") | AC15: =IF(COUNT(AA15,AB15)=2, AA15-AB15, "") | AD15: =IFERROR(AB15/AA15,"") | AE15: =IF(AND(M15="",S15="",Y15=""),"",IFERROR(M15+S15+Y15,"")) | AG15: =IF(AND(O15="",U15="",AA15=""),"",IFERROR(O15+U15+AA15,"")) | AH15: =IF(AND(P15="",V15="",AB15=""),"",IFERROR(P15+V15+AB15,"")) | AI15: =IF(AND(Q15="",W15="",AC15=""),"",IFERROR(Q15+W15+AC15,"")) | AJ15: =IFERROR(AH15/AG15,"")
A16: 14 | B16: =IFERROR(IF(H16<>"",RANK(H16,$H$3:$H$400,1),""),"") -> 14 | C16: =IFERROR(IF(J16="Completed",COUNTIFS(J$3:J$400,"Completed",I$3:I$400,"<"&I16,I$3:I$400,"<>"&"")+COUNTIFS(J$3:J$400,"Completed",I$3:I$400,"="&I16,A$3:A$400,"<="&A16,I$3:I$400,"<>"&""),""),"") | D16: SimCAT 7 | E16: IMS | F16: SimCAT | G16: Proctored | H16: 46220 | J16: =IF(I16<>"","Completed","Pending") -> Pending | K16: No | Q16: =IF(COUNT(O16,P16)=2, O16-P16, "") | R16: =IFERROR(P16/O16,"") | W16: =IF(COUNT(U16,V16)=2, U16-V16, "") | X16: =IFERROR(V16/U16,"") | AC16: =IF(COUNT(AA16,AB16)=2, AA16-AB16, "") | AD16: =IFERROR(AB16/AA16,"") | AE16: =IF(AND(M16="",S16="",Y16=""),"",IFERROR(M16+S16+Y16,"")) | AG16: =IF(AND(O16="",U16="",AA16=""),"",IFERROR(O16+U16+AA16,"")) | AH16: =IF(AND(P16="",V16="",AB16=""),"",IFERROR(P16+V16+AB16,"")) | AI16: =IF(AND(Q16="",W16="",AC16=""),"",IFERROR(Q16+W16+AC16,"")) | AJ16: =IFERROR(AH16/AG16,"")
A17: 15 | B17: =IFERROR(IF(H17<>"",RANK(H17,$H$3:$H$400,1),""),"") -> 15 | C17: =IFERROR(IF(J17="Completed",COUNTIFS(J$3:J$400,"Completed",I$3:I$400,"<"&I17,I$3:I$400,"<>"&"")+COUNTIFS(J$3:J$400,"Completed",I$3:I$400,"="&I17,A$3:A$400,"<="&A17,I$3:I$400,"<>"&""),""),"") | D17: CAT 2021 Slot 3 | E17: IMS | F17: Previous CAT | G17: Past CAT Paper | H17: 46225 | J17: =IF(I17<>"","Completed","Pending") -> Pending | K17: No | Q17: =IF(COUNT(O17,P17)=2, O17-P17, "") | R17: =IFERROR(P17/O17,"") | W17: =IF(COUNT(U17,V17)=2, U17-V17, "") | X17: =IFERROR(V17/U17,"") | AC17: =IF(COUNT(AA17,AB17)=2, AA17-AB17, "") | AD17: =IFERROR(AB17/AA17,"") | AE17: =IF(AND(M17="",S17="",Y17=""),"",IFERROR(M17+S17+Y17,"")) | AG17: =IF(AND(O17="",U17="",AA17=""),"",IFERROR(O17+U17+AA17,"")) | AH17: =IF(AND(P17="",V17="",AB17=""),"",IFERROR(P17+V17+AB17,"")) | AI17: =IF(AND(Q17="",W17="",AC17=""),"",IFERROR(Q17+W17+AC17,"")) | AJ17: =IFERROR(AH17/AG17,"")
A18: 16 | B18: =IFERROR(IF(H18<>"",RANK(H18,$H$3:$H$400,1),""),"") -> 16 | C18: =IFERROR(IF(J18="Completed",COUNTIFS(J$3:J$400,"Completed",I$3:I$400,"<"&I18,I$3:I$400,"<>"&"")+COUNTIFS(J$3:J$400,"Completed",I$3:I$400,"="&I18,A$3:A$400,"<="&A18,I$3:I$400,"<>"&""),""),"") | D18: Take Home 6 | E18: IMS | F18: Take Home | G18: Take Home | H18: 46228 | J18: =IF(I18<>"","Completed","Pending") -> Pending | K18: No | Q18: =IF(COUNT(O18,P18)=2, O18-P18, "") | R18: =IFERROR(P18/O18,"") | W18: =IF(COUNT(U18,V18)=2, U18-V18, "") | X18: =IFERROR(V18/U18,"") | AC18: =IF(COUNT(AA18,AB18)=2, AA18-AB18, "") | AD18: =IFERROR(AB18/AA18,"") | AE18: =IF(AND(M18="",S18="",Y18=""),"",IFERROR(M18+S18+Y18,"")) | AG18: =IF(AND(O18="",U18="",AA18=""),"",IFERROR(O18+U18+AA18,"")) | AH18: =IF(AND(P18="",V18="",AB18=""),"",IFERROR(P18+V18+AB18,"")) | AI18: =IF(AND(Q18="",W18="",AC18=""),"",IFERROR(Q18+W18+AC18,"")) | AJ18: =IFERROR(AH18/AG18,"")
A19: 17 | B19: =IFERROR(IF(H19<>"",RANK(H19,$H$3:$H$400,1),""),"") -> 17 | C19: =IFERROR(IF(J19="Completed",COUNTIFS(J$3:J$400,"Completed",I$3:I$400,"<"&I19,I$3:I$400,"<>"&"")+COUNTIFS(J$3:J$400,"Completed",I$3:I$400,"="&I19,A$3:A$400,"<="&A19,I$3:I$400,"<>"&""),""),"") | D19: Headstart CAT 1 | E19: Cracku | F19: Headstart CAT | G19: Take Home | H19: 46229 | J19: =IF(I19<>"","Completed","Pending") -> Pending | K19: No | Q19: =IF(COUNT(O19,P19)=2, O19-P19, "") | R19: =IFERROR(P19/O19,"") | W19: =IF(COUNT(U19,V19)=2, U19-V19, "") | X19: =IFERROR(V19/U19,"") | AC19: =IF(COUNT(AA19,AB19)=2, AA19-AB19, "") | AD19: =IFERROR(AB19/AA19,"") | AE19: =IF(AND(M19="",S19="",Y19=""),"",IFERROR(M19+S19+Y19,"")) | AG19: =IF(AND(O19="",U19="",AA19=""),"",IFERROR(O19+U19+AA19,"")) | AH19: =IF(AND(P19="",V19="",AB19=""),"",IFERROR(P19+V19+AB19,"")) | AI19: =IF(AND(Q19="",W19="",AC19=""),"",IFERROR(Q19+W19+AC19,"")) | AJ19: =IFERROR(AH19/AG19,"")
A20: 18 | B20: =IFERROR(IF(H20<>"",RANK(H20,$H$3:$H$400,1),""),"") -> 18 | C20: =IFERROR(IF(J20="Completed",COUNTIFS(J$3:J$400,"Completed",I$3:I$400,"<"&I20,I$3:I$400,"<>"&"")+COUNTIFS(J$3:J$400,"Completed",I$3:I$400,"="&I20,A$3:A$400,"<="&A20,I$3:I$400,"<>"&""),""),"") | D20: DashCAT 1 | E20: Cracku | F20: DashCAT | G20: Take Home | H20: 46231 | J20: =IF(I20<>"","Completed","Pending") -> Pending | K20: No | Q20: =IF(COUNT(O20,P20)=2, O20-P20, "") | R20: =IFERROR(P20/O20,"") | W20: =IF(COUNT(U20,V20)=2, U20-V20, "") | X20: =IFERROR(V20/U20,"") | AC20: =IF(COUNT(AA20,AB20)=2, AA20-AB20, "") | AD20: =IFERROR(AB20/AA20,"") | AE20: =IF(AND(M20="",S20="",Y20=""),"",IFERROR(M20+S20+Y20,"")) | AG20: =IF(AND(O20="",U20="",AA20=""),"",IFERROR(O20+U20+AA20,"")) | AH20: =IF(AND(P20="",V20="",AB20=""),"",IFERROR(P20+V20+AB20,"")) | AI20: =IF(AND(Q20="",W20="",AC20=""),"",IFERROR(Q20+W20+AC20,"")) | AJ20: =IFERROR(AH20/AG20,"")
A21: 19 | B21: =IFERROR(IF(H21<>"",RANK(H21,$H$3:$H$400,1),""),"") -> 19 | C21: =IFERROR(IF(J21="Completed",COUNTIFS(J$3:J$400,"Completed",I$3:I$400,"<"&I21,I$3:I$400,"<>"&"")+COUNTIFS(J$3:J$400,"Completed",I$3:I$400,"="&I21,A$3:A$400,"<="&A21,I$3:I$400,"<>"&""),""),"") | D21: DashCAT 2 | E21: Cracku | F21: DashCAT | G21: Take Home | H21: 46232 | J21: =IF(I21<>"","Completed","Pending") -> Pending | K21: No | Q21: =IF(COUNT(O21,P21)=2, O21-P21, "") | R21: =IFERROR(P21/O21,"") | W21: =IF(COUNT(U21,V21)=2, U21-V21, "") | X21: =IFERROR(V21/U21,"") | AC21: =IF(COUNT(AA21,AB21)=2, AA21-AB21, "") | AD21: =IFERROR(AB21/AA21,"") | AE21: =IF(AND(M21="",S21="",Y21=""),"",IFERROR(M21+S21+Y21,"")) | AG21: =IF(AND(O21="",U21="",AA21=""),"",IFERROR(O21+U21+AA21,"")) | AH21: =IF(AND(P21="",V21="",AB21=""),"",IFERROR(P21+V21+AB21,"")) | AI21: =IF(AND(Q21="",W21="",AC21=""),"",IFERROR(Q21+W21+AC21,"")) | AJ21: =IFERROR(AH21/AG21,"")
A22: 20 | B22: =IFERROR(IF(H22<>"",RANK(H22,$H$3:$H$400,1),""),"") -> 20 | C22: =IFERROR(IF(J22="Completed",COUNTIFS(J$3:J$400,"Completed",I$3:I$400,"<"&I22,I$3:I$400,"<>"&"")+COUNTIFS(J$3:J$400,"Completed",I$3:I$400,"="&I22,A$3:A$400,"<="&A22,I$3:I$400,"<>"&""),""),"") | D22: SimCAT 8 | E22: IMS | F22: SimCAT | G22: Proctored | H22: 46234 | J22: =IF(I22<>"","Completed","Pending") -> Pending | K22: No | Q22: =IF(COUNT(O22,P22)=2, O22-P22, "") | R22: =IFERROR(P22/O22,"") | W22: =IF(COUNT(U22,V22)=2, U22-V22, "") | X22: =IFERROR(V22/U22,"") | AC22: =IF(COUNT(AA22,AB22)=2, AA22-AB22, "") | AD22: =IFERROR(AB22/AA22,"") | AE22: =IF(AND(M22="",S22="",Y22=""),"",IFERROR(M22+S22+Y22,"")) | AG22: =IF(AND(O22="",U22="",AA22=""),"",IFERROR(O22+U22+AA22,"")) | AH22: =IF(AND(P22="",V22="",AB22=""),"",IFERROR(P22+V22+AB22,"")) | AI22: =IF(AND(Q22="",W22="",AC22=""),"",IFERROR(Q22+W22+AC22,"")) | AJ22: =IFERROR(AH22/AG22,"")
A23: 21 | B23: =IFERROR(IF(H23<>"",RANK(H23,$H$3:$H$400,1),""),"") -> 21 | C23: =IFERROR(IF(J23="Completed",COUNTIFS(J$3:J$400,"Completed",I$3:I$400,"<"&I23,I$3:I$400,"<>"&"")+COUNTIFS(J$3:J$400,"Completed",I$3:I$400,"="&I23,A$3:A$400,"<="&A23,I$3:I$400,"<>"&""),""),"") | D23: Take Home 7 | E23: IMS | F23: Take Home | G23: Take Home | H23: 46239 | J23: =IF(I23<>"","Completed","Pending") -> Pending | K23: No | Q23: =IF(COUNT(O23,P23)=2, O23-P23, "") | R23: =IFERROR(P23/O23,"") | W23: =IF(COUNT(U23,V23)=2, U23-V23, "") | X23: =IFERROR(V23/U23,"") | AC23: =IF(COUNT(AA23,AB23)=2, AA23-AB23, "") | AD23: =IFERROR(AB23/AA23,"") | AE23: =IF(AND(M23="",S23="",Y23=""),"",IFERROR(M23+S23+Y23,"")) | AG23: =IF(AND(O23="",U23="",AA23=""),"",IFERROR(O23+U23+AA23,"")) | AH23: =IF(AND(P23="",V23="",AB23=""),"",IFERROR(P23+V23+AB23,"")) | AI23: =IF(AND(Q23="",W23="",AC23=""),"",IFERROR(Q23+W23+AC23,"")) | AJ23: =IFERROR(AH23/AG23,"")
A24: 22 | B24: =IFERROR(IF(H24<>"",RANK(H24,$H$3:$H$400,1),""),"") -> 22 | C24: =IFERROR(IF(J24="Completed",COUNTIFS(J$3:J$400,"Completed",I$3:I$400,"<"&I24,I$3:I$400,"<>"&"")+COUNTIFS(J$3:J$400,"Completed",I$3:I$400,"="&I24,A$3:A$400,"<="&A24,I$3:I$400,"<>"&""),""),"") | D24: SimCAT 9 | E24: IMS | F24: SimCAT | G24: Proctored | H24: 46243 | J24: =IF(I24<>"","Completed","Pending") -> Pending | K24: No | Q24: =IF(COUNT(O24,P24)=2, O24-P24, "") | R24: =IFERROR(P24/O24,"") | W24: =IF(COUNT(U24,V24)=2, U24-V24, "") | X24: =IFERROR(V24/U24,"") | AC24: =IF(COUNT(AA24,AB24)=2, AA24-AB24, "") | AD24: =IFERROR(AB24/AA24,"") | AE24: =IF(AND(M24="",S24="",Y24=""),"",IFERROR(M24+S24+Y24,"")) | AG24: =IF(AND(O24="",U24="",AA24=""),"",IFERROR(O24+U24+AA24,"")) | AH24: =IF(AND(P24="",V24="",AB24=""),"",IFERROR(P24+V24+AB24,"")) | AI24: =IF(AND(Q24="",W24="",AC24=""),"",IFERROR(Q24+W24+AC24,"")) | AJ24: =IFERROR(AH24/AG24,"")
... A102: 100 | B102: =IFERROR(IF(H102<>"",RANK(H102,$H$3:$H$400,1),""),"") -> 100 | C102: =IFERROR(IF(J102="Completed",COUNTIFS(J$3:J$400,"Completed",I$3:I$400,"<"&I102,I$3:I$400,"<>"&"")+COUNTIFS(J$3:J$400,"Completed",I$3:I$400,"="&I102,A$3:A$400,"<="&A102,I$3:I$400,"<>"&""),""),"") | D102: CAT 2025 Slot 3 | E102: IMS | F102: Previous CAT | G102: Past CAT Paper | H102: 46353 | J102: =IF(I102<>"","Completed","Pending") -> Pending | K102: No | Q102: =IF(COUNT(O102,P102)=2, O102-P102, "") | R102: =IFERROR(P102/O102,"") | W102: =IF(COUNT(U102,V102)=2, U102-V102, "") | X102: =IFERROR(V102/U102,"") | AC102: =IF(COUNT(AA102,AB102)=2, AA102-AB102, "") | AD102: =IFERROR(AB102/AA102,"") | AE102: =IF(AND(M102="",S102="",Y102=""),"",IFERROR(M102+S102+Y102,"")) | AG102: =IF(AND(O102="",U102="",AA102=""),"",IFERROR(O102+U102+AA102,"")) | AH102: =IF(AND(P102="",V102="",AB102=""),"",IFERROR(P102+V102+AB102,"")) | AI102: =IF(AND(Q102="",W102="",AC102=""),"",IFERROR(Q102+W102+AC102,"")) | AJ102: =IFERROR(AH102/AG102,"")
A103: 101 | B103: =IFERROR(IF(H103<>"",RANK(H103,$H$3:$H$400,1),""),"") | C103: =IFERROR(IF(J103="Completed",COUNTIFS(J$3:J$400,"Completed",I$3:I$400,"<"&I103,I$3:I$400,"<>"&"")+COUNTIFS(J$3:J$400,"Completed",I$3:I$400,"="&I103,A$3:A$400,"<="&A103,I$3:I$400,"<>"&""),""),"") | J103: =IF(I103<>"","Completed","Pending") -> Pending | K103: No | Q103: =IF(COUNT(O103,P103)=2, O103-P103, "") | R103: =IFERROR(P103/O103,"") | W103: =IF(COUNT(U103,V103)=2, U103-V103, "") | X103: =IFERROR(V103/U103,"") | AC103: =IF(COUNT(AA103,AB103)=2, AA103-AB103, "") | AD103: =IFERROR(AB103/AA103,"") | AE103: =IF(AND(M103="",S103="",Y103=""),"",IFERROR(M103+S103+Y103,"")) | AG103: =IF(AND(O103="",U103="",AA103=""),"",IFERROR(O103+U103+AA103,"")) | AH103: =IF(AND(P103="",V103="",AB103=""),"",IFERROR(P103+V103+AB103,"")) | AI103: =IF(AND(Q103="",W103="",AC103=""),"",IFERROR(Q103+W103+AC103,"")) | AJ103: =IFERROR(AH103/AG103,"")
A104: 102 | B104: =IFERROR(IF(H104<>"",RANK(H104,$H$3:$H$400,1),""),"") | C104: =IFERROR(IF(J104="Completed",COUNTIFS(J$3:J$400,"Completed",I$3:I$400,"<"&I104,I$3:I$400,"<>"&"")+COUNTIFS(J$3:J$400,"Completed",I$3:I$400,"="&I104,A$3:A$400,"<="&A104,I$3:I$400,"<>"&""),""),"") | J104: =IF(I104<>"","Completed","Pending") -> Pending | K104: No | Q104: =IF(COUNT(O104,P104)=2, O104-P104, "") | R104: =IFERROR(P104/O104,"") | W104: =IF(COUNT(U104,V104)=2, U104-V104, "") | X104: =IFERROR(V104/U104,"") | AC104: =IF(COUNT(AA104,AB104)=2, AA104-AB104, "") | AD104: =IFERROR(AB104/AA104,"") | AE104: =IF(AND(M104="",S104="",Y104=""),"",IFERROR(M104+S104+Y104,"")) | AG104: =IF(AND(O104="",U104="",AA104=""),"",IFERROR(O104+U104+AA104,"")) | AH104: =IF(AND(P104="",V104="",AB104=""),"",IFERROR(P104+V104+AB104,"")) | AI104: =IF(AND(Q104="",W104="",AC104=""),"",IFERROR(Q104+W104+AC104,"")) | AJ104: =IFERROR(AH104/AG104,"")
A105: 103 | B105: =IFERROR(IF(H105<>"",RANK(H105,$H$3:$H$400,1),""),"") | C105: =IFERROR(IF(J105="Completed",COUNTIFS(J$3:J$400,"Completed",I$3:I$400,"<"&I105,I$3:I$400,"<>"&"")+COUNTIFS(J$3:J$400,"Completed",I$3:I$400,"="&I105,A$3:A$400,"<="&A105,I$3:I$400,"<>"&""),""),"") | J105: =IF(I105<>"","Completed","Pending") -> Pending | K105: No | Q105: =IF(COUNT(O105,P105)=2, O105-P105, "") | R105: =IFERROR(P105/O105,"") | W105: =IF(COUNT(U105,V105)=2, U105-V105, "") | X105: =IFERROR(V105/U105,"") | AC105: =IF(COUNT(AA105,AB105)=2, AA105-AB105, "") | AD105: =IFERROR(AB105/AA105,"") | AE105: =IF(AND(M105="",S105="",Y105=""),"",IFERROR(M105+S105+Y105,"")) | AG105: =IF(AND(O105="",U105="",AA105=""),"",IFERROR(O105+U105+AA105,"")) | AH105: =IF(AND(P105="",V105="",AB105=""),"",IFERROR(P105+V105+AB105,"")) | AI105: =IF(AND(Q105="",W105="",AC105=""),"",IFERROR(Q105+W105+AC105,"")) | AJ105: =IFERROR(AH105/AG105,"")
A106: 104 | B106: =IFERROR(IF(H106<>"",RANK(H106,$H$3:$H$400,1),""),"") | C106: =IFERROR(IF(J106="Completed",COUNTIFS(J$3:J$400,"Completed",I$3:I$400,"<"&I106,I$3:I$400,"<>"&"")+COUNTIFS(J$3:J$400,"Completed",I$3:I$400,"="&I106,A$3:A$400,"<="&A106,I$3:I$400,"<>"&""),""),"") | J106: =IF(I106<>"","Completed","Pending") -> Pending | K106: No | Q106: =IF(COUNT(O106,P106)=2, O106-P106, "") | R106: =IFERROR(P106/O106,"") | W106: =IF(COUNT(U106,V106)=2, U106-V106, "") | X106: =IFERROR(V106/U106,"") | AC106: =IF(COUNT(AA106,AB106)=2, AA106-AB106, "") | AD106: =IFERROR(AB106/AA106,"") | AE106: =IF(AND(M106="",S106="",Y106=""),"",IFERROR(M106+S106+Y106,"")) | AG106: =IF(AND(O106="",U106="",AA106=""),"",IFERROR(O106+U106+AA106,"")) | AH106: =IF(AND(P106="",V106="",AB106=""),"",IFERROR(P106+V106+AB106,"")) | AI106: =IF(AND(Q106="",W106="",AC106=""),"",IFERROR(Q106+W106+AC106,"")) | AJ106: =IFERROR(AH106/AG106,"")
A107: 105 | B107: =IFERROR(IF(H107<>"",RANK(H107,$H$3:$H$400,1),""),"") | C107: =IFERROR(IF(J107="Completed",COUNTIFS(J$3:J$400,"Completed",I$3:I$400,"<"&I107,I$3:I$400,"<>"&"")+COUNTIFS(J$3:J$400,"Completed",I$3:I$400,"="&I107,A$3:A$400,"<="&A107,I$3:I$400,"<>"&""),""),"") | J107: =IF(I107<>"","Completed","Pending") -> Pending | K107: No | Q107: =IF(COUNT(O107,P107)=2, O107-P107, "") | R107: =IFERROR(P107/O107,"") | W107: =IF(COUNT(U107,V107)=2, U107-V107, "") | X107: =IFERROR(V107/U107,"") | AC107: =IF(COUNT(AA107,AB107)=2, AA107-AB107, "") | AD107: =IFERROR(AB107/AA107,"") | AE107: =IF(AND(M107="",S107="",Y107=""),"",IFERROR(M107+S107+Y107,"")) | AG107: =IF(AND(O107="",U107="",AA107=""),"",IFERROR(O107+U107+AA107,"")) | AH107: =IF(AND(P107="",V107="",AB107=""),"",IFERROR(P107+V107+AB107,"")) | AI107: =IF(AND(Q107="",W107="",AC107=""),"",IFERROR(Q107+W107+AC107,"")) | AJ107: =IFERROR(AH107/AG107,"")
A108: 106 | B108: =IFERROR(IF(H108<>"",RANK(H108,$H$3:$H$400,1),""),"") | C108: =IFERROR(IF(J108="Completed",COUNTIFS(J$3:J$400,"Completed",I$3:I$400,"<"&I108,I$3:I$400,"<>"&"")+COUNTIFS(J$3:J$400,"Completed",I$3:I$400,"="&I108,A$3:A$400,"<="&A108,I$3:I$400,"<>"&""),""),"") | J108: =IF(I108<>"","Completed","Pending") -> Pending | K108: No | Q108: =IF(COUNT(O108,P108)=2, O108-P108, "") | R108: =IFERROR(P108/O108,"") | W108: =IF(COUNT(U108,V108)=2, U108-V108, "") | X108: =IFERROR(V108/U108,"") | AC108: =IF(COUNT(AA108,AB108)=2, AA108-AB108, "") | AD108: =IFERROR(AB108/AA108,"") | AE108: =IF(AND(M108="",S108="",Y108=""),"",IFERROR(M108+S108+Y108,"")) | AG108: =IF(AND(O108="",U108="",AA108=""),"",IFERROR(O108+U108+AA108,"")) | AH108: =IF(AND(P108="",V108="",AB108=""),"",IFERROR(P108+V108+AB108,"")) | AI108: =IF(AND(Q108="",W108="",AC108=""),"",IFERROR(Q108+W108+AC108,"")) | AJ108: =IFERROR(AH108/AG108,"")
A109: 107 | B109: =IFERROR(IF(H109<>"",RANK(H109,$H$3:$H$400,1),""),"") | C109: =IFERROR(IF(J109="Completed",COUNTIFS(J$3:J$400,"Completed",I$3:I$400,"<"&I109,I$3:I$400,"<>"&"")+COUNTIFS(J$3:J$400,"Completed",I$3:I$400,"="&I109,A$3:A$400,"<="&A109,I$3:I$400,"<>"&""),""),"") | J109: =IF(I109<>"","Completed","Pending") -> Pending | K109: No | Q109: =IF(COUNT(O109,P109)=2, O109-P109, "") | R109: =IFERROR(P109/O109,"") | W109: =IF(COUNT(U109,V109)=2, U109-V109, "") | X109: =IFERROR(V109/U109,"") | AC109: =IF(COUNT(AA109,AB109)=2, AA109-AB109, "") | AD109: =IFERROR(AB109/AA109,"") | AE109: =IF(AND(M109="",S109="",Y109=""),"",IFERROR(M109+S109+Y109,"")) | AG109: =IF(AND(O109="",U109="",AA109=""),"",IFERROR(O109+U109+AA109,"")) | AH109: =IF(AND(P109="",V109="",AB109=""),"",IFERROR(P109+V109+AB109,"")) | AI109: =IF(AND(Q109="",W109="",AC109=""),"",IFERROR(Q109+W109+AC109,"")) | AJ109: =IFERROR(AH109/AG109,"")
A110: 108 | B110: =IFERROR(IF(H110<>"",RANK(H110,$H$3:$H$400,1),""),"") | C110: =IFERROR(IF(J110="Completed",COUNTIFS(J$3:J$400,"Completed",I$3:I$400,"<"&I110,I$3:I$400,"<>"&"")+COUNTIFS(J$3:J$400,"Completed",I$3:I$400,"="&I110,A$3:A$400,"<="&A110,I$3:I$400,"<>"&""),""),"") | J110: =IF(I110<>"","Completed","Pending") -> Pending | K110: No | Q110: =IF(COUNT(O110,P110)=2, O110-P110, "") | R110: =IFERROR(P110/O110,"") | W110: =IF(COUNT(U110,V110)=2, U110-V110, "") | X110: =IFERROR(V110/U110,"") | AC110: =IF(COUNT(AA110,AB110)=2, AA110-AB110, "") | AD110: =IFERROR(AB110/AA110,"") | AE110: =IF(AND(M110="",S110="",Y110=""),"",IFERROR(M110+S110+Y110,"")) | AG110: =IF(AND(O110="",U110="",AA110=""),"",IFERROR(O110+U110+AA110,"")) | AH110: =IF(AND(P110="",V110="",AB110=""),"",IFERROR(P110+V110+AB110,"")) | AI110: =IF(AND(Q110="",W110="",AC110=""),"",IFERROR(Q110+W110+AC110,"")) | AJ110: =IFERROR(AH110/AG110,"")
A111: 109 | B111: =IFERROR(IF(H111<>"",RANK(H111,$H$3:$H$400,1),""),"") | C111: =IFERROR(IF(J111="Completed",COUNTIFS(J$3:J$400,"Completed",I$3:I$400,"<"&I111,I$3:I$400,"<>"&"")+COUNTIFS(J$3:J$400,"Completed",I$3:I$400,"="&I111,A$3:A$400,"<="&A111,I$3:I$400,"<>"&""),""),"") | J111: =IF(I111<>"","Completed","Pending") -> Pending | K111: No | Q111: =IF(COUNT(O111,P111)=2, O111-P111, "") | R111: =IFERROR(P111/O111,"") | W111: =IF(COUNT(U111,V111)=2, U111-V111, "") | X111: =IFERROR(V111/U111,"") | AC111: =IF(COUNT(AA111,AB111)=2, AA111-AB111, "") | AD111: =IFERROR(AB111/AA111,"") | AE111: =IF(AND(M111="",S111="",Y111=""),"",IFERROR(M111+S111+Y111,"")) | AG111: =IF(AND(O111="",U111="",AA111=""),"",IFERROR(O111+U111+AA111,"")) | AH111: =IF(AND(P111="",V111="",AB111=""),"",IFERROR(P111+V111+AB111,"")) | AI111: =IF(AND(Q111="",W111="",AC111=""),"",IFERROR(Q111+W111+AC111,"")) | AJ111: =IFERROR(AH111/AG111,"")
A112: 110 | B112: =IFERROR(IF(H112<>"",RANK(H112,$H$3:$H$400,1),""),"") | C112: =IFERROR(IF(J112="Completed",COUNTIFS(J$3:J$400,"Completed",I$3:I$400,"<"&I112,I$3:I$400,"<>"&"")+COUNTIFS(J$3:J$400,"Completed",I$3:I$400,"="&I112,A$3:A$400,"<="&A112,I$3:I$400,"<>"&""),""),"") | J112: =IF(I112<>"","Completed","Pending") -> Pending | K112: No | Q112: =IF(COUNT(O112,P112)=2, O112-P112, "") | R112: =IFERROR(P112/O112,"") | W112: =IF(COUNT(U112,V112)=2, U112-V112, "") | X112: =IFERROR(V112/U112,"") | AC112: =IF(COUNT(AA112,AB112)=2, AA112-AB112, "") | AD112: =IFERROR(AB112/AA112,"") | AE112: =IF(AND(M112="",S112="",Y112=""),"",IFERROR(M112+S112+Y112,"")) | AG112: =IF(AND(O112="",U112="",AA112=""),"",IFERROR(O112+U112+AA112,"")) | AH112: =IF(AND(P112="",V112="",AB112=""),"",IFERROR(P112+V112+AB112,"")) | AI112: =IF(AND(Q112="",W112="",AC112=""),"",IFERROR(Q112+W112+AC112,"")) | AJ112: =IFERROR(AH112/AG112,"")
A113: 111 | B113: =IFERROR(IF(H113<>"",RANK(H113,$H$3:$H$400,1),""),"") | C113: =IFERROR(IF(J113="Completed",COUNTIFS(J$3:J$400,"Completed",I$3:I$400,"<"&I113,I$3:I$400,"<>"&"")+COUNTIFS(J$3:J$400,"Completed",I$3:I$400,"="&I113,A$3:A$400,"<="&A113,I$3:I$400,"<>"&""),""),"") | J113: =IF(I113<>"","Completed","Pending") -> Pending | K113: No | Q113: =IF(COUNT(O113,P113)=2, O113-P113, "") | R113: =IFERROR(P113/O113,"") | W113: =IF(COUNT(U113,V113)=2, U113-V113, "") | X113: =IFERROR(V113/U113,"") | AC113: =IF(COUNT(AA113,AB113)=2, AA113-AB113, "") | AD113: =IFERROR(AB113/AA113,"") | AE113: =IF(AND(M113="",S113="",Y113=""),"",IFERROR(M113+S113+Y113,"")) | AG113: =IF(AND(O113="",U113="",AA113=""),"",IFERROR(O113+U113+AA113,"")) | AH113: =IF(AND(P113="",V113="",AB113=""),"",IFERROR(P113+V113+AB113,"")) | AI113: =IF(AND(Q113="",W113="",AC113=""),"",IFERROR(Q113+W113+AC113,"")) | AJ113: =IFERROR(AH113/AG113,"")
A114: 112 | B114: =IFERROR(IF(H114<>"",RANK(H114,$H$3:$H$400,1),""),"") | C114: =IFERROR(IF(J114="Completed",COUNTIFS(J$3:J$400,"Completed",I$3:I$400,"<"&I114,I$3:I$400,"<>"&"")+COUNTIFS(J$3:J$400,"Completed",I$3:I$400,"="&I114,A$3:A$400,"<="&A114,I$3:I$400,"<>"&""),""),"") | J114: =IF(I114<>"","Completed","Pending") -> Pending | K114: No | Q114: =IF(COUNT(O114,P114)=2, O114-P114, "") | R114: =IFERROR(P114/O114,"") | W114: =IF(COUNT(U114,V114)=2, U114-V114, "") | X114: =IFERROR(V114/U114,"") | AC114: =IF(COUNT(AA114,AB114)=2, AA114-AB114, "") | AD114: =IFERROR(AB114/AA114,"") | AE114: =IF(AND(M114="",S114="",Y114=""),"",IFERROR(M114+S114+Y114,"")) | AG114: =IF(AND(O114="",U114="",AA114=""),"",IFERROR(O114+U114+AA114,"")) | AH114: =IF(AND(P114="",V114="",AB114=""),"",IFERROR(P114+V114+AB114,"")) | AI114: =IF(AND(Q114="",W114="",AC114=""),"",IFERROR(Q114+W114+AC114,"")) | AJ114: =IFERROR(AH114/AG114,"")
... A152: 150 | B152: =IFERROR(IF(H152<>"",RANK(H152,$H$3:$H$400,1),""),"") | C152: =IFERROR(IF(J152="Completed",COUNTIFS(J$3:J$400,"Completed",I$3:I$400,"<"&I152,I$3:I$400,"<>"&"")+COUNTIFS(J$3:J$400,"Completed",I$3:I$400,"="&I152,A$3:A$400,"<="&A152,I$3:I$400,"<>"&""),""),"") | J152: =IF(I152<>"","Completed","Pending") -> Pending | K152: No | Q152: =IF(COUNT(O152,P152)=2, O152-P152, "") | R152: =IFERROR(P152/O152,"") | W152: =IF(COUNT(U152,V152)=2, U152-V152, "") | X152: =IFERROR(V152/U152,"") | AC152: =IF(COUNT(AA152,AB152)=2, AA152-AB152, "") | AD152: =IFERROR(AB152/AA152,"") | AE152: =IF(AND(M152="",S152="",Y152=""),"",IFERROR(M152+S152+Y152,"")) | AG152: =IF(AND(O152="",U152="",AA152=""),"",IFERROR(O152+U152+AA152,"")) | AH152: =IF(AND(P152="",V152="",AB152=""),"",IFERROR(P152+V152+AB152,"")) | AI152: =IF(AND(Q152="",W152="",AC152=""),"",IFERROR(Q152+W152+AC152,"")) | AJ152: =IFERROR(AH152/AG152,"")
A154: ★ Made by Devansh Gohil · CAT 2026 Analytics · Formula-driven · Excel & Google Sheets compatible

Sheet Calculations
A1: Metric | B1: Ovr Score | C1: Ovr %ile | D1: VARC Score | E1: VARC %ile | F1: DILR Score | G1: DILR %ile | H1: QA Score | I1: QA %ile | K1: LatestIdx
A2: Latest | B2: {=IF($K$2="","",IF(INDEX(Chart_Data!$J$2:$J$401,$K$2)="","",INDEX(Chart_Data!$J$2:$J$401,$K$2)))} -> 55 | C2: {=IF($K$2="","",IF(INDEX(Chart_Data!$K$2:$K$401,$K$2)="","",INDEX(Chart_Data!$K$2:$K$401,$K$2)))} -> 79.22 | D2: {=IF($K$2="","",IF(INDEX(Chart_Data!$D$2:$D$401,$K$2)="","",INDEX(Chart_Data!$D$2:$D$401,$K$2)))} -> 20 | E2: {=IF($K$2="","",IF(INDEX(Chart_Data!$E$2:$E$401,$K$2)="","",INDEX(Chart_Data!$E$2:$E$401,$K$2)))} -> 65.51 | F2: {=IF($K$2="","",IF(INDEX(Chart_Data!$F$2:$F$401,$K$2)="","",INDEX(Chart_Data!$F$2:$F$401,$K$2)))} -> 16 | G2: {=IF($K$2="","",IF(INDEX(Chart_Data!$G$2:$G$401,$K$2)="","",INDEX(Chart_Data!$G$2:$G$401,$K$2)))} -> 83.74 | H2: {=IF($K$2="","",IF(INDEX(Chart_Data!$H$2:$H$401,$K$2)="","",INDEX(Chart_Data!$H$2:$H$401,$K$2)))} -> 19 | I2: {=IF($K$2="","",IF(INDEX(Chart_Data!$I$2:$I$401,$K$2)="","",INDEX(Chart_Data!$I$2:$I$401,$K$2)))} -> 69.82 | K2: =IFERROR(COUNT(Chart_Data!$J$2:$J$401),"") -> 10
A3: Average | B3: =IFERROR(AVERAGE(Chart_Data!$J$2:$J$401),"") -> 79.1 | C3: =IFERROR(AVERAGE(Chart_Data!$K$2:$K$401),"") -> 92.015556 | D3: =IFERROR(AVERAGE(Chart_Data!$D$2:$D$401),"") -> 38.4 | E3: =IFERROR(AVERAGE(Chart_Data!$E$2:$E$401),"") -> 92.475556 | F3: =IFERROR(AVERAGE(Chart_Data!$F$2:$F$401),"") -> 20.7 | G3: =IFERROR(AVERAGE(Chart_Data!$G$2:$G$401),"") -> 77.814444 | H3: =IFERROR(AVERAGE(Chart_Data!$H$2:$H$401),"") -> 20 | I3: =IFERROR(AVERAGE(Chart_Data!$I$2:$I$401),"") -> 71.315556
A4: Median | B4: =IFERROR(MEDIAN(Chart_Data!$J$2:$J$401),"") -> 82.5 | C4: =IFERROR(MEDIAN(Chart_Data!$K$2:$K$401),"") -> 94.82 | D4: =IFERROR(MEDIAN(Chart_Data!$D$2:$D$401),"") -> 37.5 | E4: =IFERROR(MEDIAN(Chart_Data!$E$2:$E$401),"") -> 98.12 | F4: =IFERROR(MEDIAN(Chart_Data!$F$2:$F$401),"") -> 22 | G4: =IFERROR(MEDIAN(Chart_Data!$G$2:$G$401),"") -> 83.74 | H4: =IFERROR(MEDIAN(Chart_Data!$H$2:$H$401),"") -> 20.5 | I4: =IFERROR(MEDIAN(Chart_Data!$I$2:$I$401),"") -> 69.82
A5: Highest | B5: =IFERROR(MAX(Chart_Data!$J$2:$J$401),"") -> 95 | C5: =IFERROR(MAX(Chart_Data!$K$2:$K$401),"") -> 98.37 | D5: =IFERROR(MAX(Chart_Data!$D$2:$D$401),"") -> 50 | E5: =IFERROR(MAX(Chart_Data!$E$2:$E$401),"") -> 99.91 | F5: =IFERROR(MAX(Chart_Data!$F$2:$F$401),"") -> 36 | G5: =IFERROR(MAX(Chart_Data!$G$2:$G$401),"") -> 94.69 | H5: =IFERROR(MAX(Chart_Data!$H$2:$H$401),"") -> 36 | I5: =IFERROR(MAX(Chart_Data!$I$2:$I$401),"") -> 96.81
A6: Lowest | B6: =IFERROR(MIN(Chart_Data!$J$2:$J$401),"") -> 55 | C6: =IFERROR(MIN(Chart_Data!$K$2:$K$401),"") -> 79.22 | D6: =IFERROR(MIN(Chart_Data!$D$2:$D$401),"") -> 20 | E6: =IFERROR(MIN(Chart_Data!$E$2:$E$401),"") -> 65.51 | F6: =IFERROR(MIN(Chart_Data!$F$2:$F$401),"") -> 3 | G6: =IFERROR(MIN(Chart_Data!$G$2:$G$401),"") -> 33.84 | H6: =IFERROR(MIN(Chart_Data!$H$2:$H$401),"") -> 10 | I6: =IFERROR(MIN(Chart_Data!$I$2:$I$401),"") -> 45.38
A7: Variance | B7: =IFERROR(VAR(Chart_Data!$J$2:$J$401),"") -> 145.43333 | C7: =IFERROR(VAR(Chart_Data!$K$2:$K$401),"") -> 42.221478 | D7: =IFERROR(VAR(Chart_Data!$D$2:$D$401),"") -> 98.266667 | E7: =IFERROR(VAR(Chart_Data!$E$2:$E$401),"") -> 121.59408 | F7: =IFERROR(VAR(Chart_Data!$F$2:$F$401),"") -> 87.344444 | G7: =IFERROR(VAR(Chart_Data!$G$2:$G$401),"") -> 377.38483 | H7: =IFERROR(VAR(Chart_Data!$H$2:$H$401),"") -> 60.888889 | I7: =IFERROR(VAR(Chart_Data!$I$2:$I$401),"") -> 253.46275
A8: StdDev | B8: =IFERROR(STDEV(Chart_Data!$J$2:$J$401),"") -> 12.059574 | C8: =IFERROR(STDEV(Chart_Data!$K$2:$K$401),"") -> 6.4978056 | D8: =IFERROR(STDEV(Chart_Data!$D$2:$D$401),"") -> 9.9129545 | E8: =IFERROR(STDEV(Chart_Data!$E$2:$E$401),"") -> 11.02697 | F8: =IFERROR(STDEV(Chart_Data!$F$2:$F$401),"") -> 9.345825 | G8: =IFERROR(STDEV(Chart_Data!$G$2:$G$401),"") -> 19.426395 | H8: =IFERROR(STDEV(Chart_Data!$H$2:$H$401),"") -> 7.8031333 | I8: =IFERROR(STDEV(Chart_Data!$I$2:$I$401),"") -> 15.920514
A9: RollAvg5 | B9: =IFERROR(AVERAGE(OFFSET(Chart_Data!$J$1,MAX(1,B13-4),0,MIN(5,B13),1)),"") -> 75.8 | C9: =IFERROR(AVERAGE(OFFSET(Chart_Data!$K$1,MAX(1,$B$13-4),0,MIN(5,$B$13),1)),"") -> 92.3775 | D9: =IFERROR(AVERAGE(OFFSET(Chart_Data!$D$1,MAX(1,D13-4),0,MIN(5,D13),1)),"") -> 37.2 | E9: =IFERROR(AVERAGE(OFFSET(Chart_Data!$E$1,MAX(1,$B$13-4),0,MIN(5,$B$13),1)),"") -> 90.79 | F9: =IFERROR(AVERAGE(OFFSET(Chart_Data!$F$1,MAX(1,F13-4),0,MIN(5,F13),1)),"") -> 16.8 | G9: =IFERROR(AVERAGE(OFFSET(Chart_Data!$G$1,MAX(1,$B$13-4),0,MIN(5,$B$13),1)),"") -> 67.3375 | H9: =IFERROR(AVERAGE(OFFSET(Chart_Data!$H$1,MAX(1,H13-4),0,MIN(5,H13),1)),"") -> 21.8 | I9: =IFERROR(AVERAGE(OFFSET(Chart_Data!$I$1,MAX(1,$B$13-4),0,MIN(5,$B$13),1)),"") -> 73.785
A10: RollAvg10 | B10: =IFERROR(AVERAGE(OFFSET(Chart_Data!$J$1,MAX(1,B13-9),0,MIN(10,B13),1)),"") -> 79.1 | C10: =IFERROR(AVERAGE(OFFSET(Chart_Data!$K$1,MAX(1,$B$13-9),0,MIN(10,$B$13),1)),"") -> 92.015556 | D10: =IFERROR(AVERAGE(OFFSET(Chart_Data!$D$1,MAX(1,D13-9),0,MIN(10,D13),1)),"") -> 38.4 | E10: =IFERROR(AVERAGE(OFFSET(Chart_Data!$E$1,MAX(1,$B$13-9),0,MIN(10,$B$13),1)),"") -> 92.475556 | F10: =IFERROR(AVERAGE(OFFSET(Chart_Data!$F$1,MAX(1,F13-9),0,MIN(10,F13),1)),"") -> 20.7 | G10: =IFERROR(AVERAGE(OFFSET(Chart_Data!$G$1,MAX(1,$B$13-9),0,MIN(10,$B$13),1)),"") -> 77.814444 | H10: =IFERROR(AVERAGE(OFFSET(Chart_Data!$H$1,MAX(1,H13-9),0,MIN(10,H13),1)),"") -> 20 | I10: =IFERROR(AVERAGE(OFFSET(Chart_Data!$I$1,MAX(1,$B$13-9),0,MIN(10,$B$13),1)),"") -> 71.315556
